Workbook

Sheet Sheet_2
B2: Text_7 | H2: 365 | I2: 93.551705 | J2: 78.479079 | K2: 78.478201 | L2: 74.914243 | M2: 365 | N2: 103.18234 | O2: 94.680586 | P2: 98.573842 | Q2: 73.549276 | R2: {=R3-M3} | S2: 106.91675 | T2: 103.10091 | U2: 80.529144 | V2: 79.418429 | W2: {=W3-R3} | X2: 78.602562 | Y2: 83.874418 | Z2: 91.901134 | AA2: 88.522799 | AB2: {=AB3-W3} | AC2: 0 | AD2: 0 | AE2: 0 | AF2: 0 | AG2: 0 | AH2: 0 | AI2: 0 | AJ2: 0 | AK2: 0 | AL2: 0 | AM2: 0 | AN2: 0 | AO2: 0 | AP2: 0 | AQ2: 0 | AR2: 0 | AS2: {=AN2} | AT2: 83.400741 | AU2: 0 | AV2: 0 | AW2: 0 | AX2: {=AS2} | AY2: 95.071445 | AZ2: 0 | BA2: 0 | BB2: 0 | BC2: {=AX2} | BD2: 77.877577 | BE2: 83.434065 | BF2: 0 | BG2: {=BB2} | BH2: {=BC2} | BI2: 86.135571 | BJ2: 89.400947 | BK2: 0 | BL2: {=BG2} | BM2: {=BH2} | BN2: 101.3804 | BO2: 80.068126 | BP2: 0 | BQ2: {=BL2} | BR2: {=BM2} | BS2: 91.518134 | BT2: 94.36389 | BU2: 0 | BV2: {=BQ2} | BW2: {=BR2} | BX2: 74.490795 | BY2: 94.914633 | BZ2: 0 | CA2: Text_8 | CB2: Text_9
B3: 0 | H3: 42185 | I3: {=H3+I2} | J3: {=I3+J2} | K3: {=J3+K2} | L3: {=K3+L2} | M3: {=EOMONTH(H3,12)} | N3: {=M3+N2} | O3: {=N3+O2} | P3: {=O3+P2} | Q3: {=P3+Q2} | R3: {=EOMONTH(M3,12)} | S3: {=R3+S2} | T3: {=S3+T2} | U3: {=T3+U2} | V3: {=U3+V2} | W3: {=EOMONTH(R3,12)} | X3: {=W3+X2} | Y3: {=X3+Y2} | Z3: {=Y3+Z2} | AA3: {=Z3+AA2} | AB3: {=EOMONTH(W3,12)} | AC3: {=EOMONTH(AB3,3)} | AD3: {=EOMONTH(AC3,3)} | AE3: {=EOMONTH(AD3,3)} | AF3: {=EOMONTH(AE3,3)} | AG3: {=EOMONTH(AB3,12)} | AH3: {=EOMONTH(AG3,3)} | AI3: {=EOMONTH(AH3,3)} | AJ3: {=EOMONTH(AI3,3)} | AK3: {=EOMONTH(AJ3,3)} | AL3: {=EOMONTH(AG3,12)} | AM3: {=EOMONTH(AL3,3)} | AN3: {=EOMONTH(AM3,3)} | AO3: {=EOMONTH(AN3,3)} | AP3: {=EOMONTH(AO3,3)} | AQ3: {=EOMONTH(AL3,12)} | AR3: {=EOMONTH(AQ3,3)} | AS3: {=AR3+AS2} | AT3: {=AS3+AT2} | AU3: {=EOMONTH(AT3,3)} | AV3: {=EOMONTH(AQ3,12)} | AW3: {=EOMONTH(AV3,3)} | AX3: {=AW3+AX2} | AY3: {=AX3+AY2} | AZ3: {=EOMONTH(AY3,3)} | BA3: {=EOMONTH(AV3,12)} | BB3: {=EOMONTH(BA3,3)} | BC3: {=BB3+BC2} | BD3: {=BC3+BD2} | BE3: {=BD3+BE2} | BF3: {=EOMONTH(BA3,12)} | BG3: {=BF3+BG2} | BH3: {=BG3+BH2} | BI3: {=BH3+BI2} | BJ3: {=BI3+BJ2} | BK3: {=EOMONTH(BF3,12)} | BL3: {=BK3+BL2} | BM3: {=BL3+BM2} | BN3: {=BM3+BN2} | BO3: {=BN3+BO2} | BP3: {=EOMONTH(BK3,12)} | BQ3: {=BP3+BQ2} | BR3: {=BQ3+BR2} | BS3: {=BR3+BS2} | BT3: {=BS3+BT2} | BU3: {=EOMONTH(BP3,12)} | BV3: {=BU3+BV2} | BW3: {=BV3+BW2} | BX3: {=BW3+BX2} | BY3: {=BX3+BY2} | BZ3: {=EOMONTH(BU3,12)} | CA3: Text_10
H4: FY15 | I4: Q116 | J4: Q216 | K4: Q316 | L4: Q416 | M4: FY16 | N4: {=LEFT(I4,2)&RIGHT(I4,2)+1} | O4: {=LEFT(J4,2)&RIGHT(J4,2)+1} | P4: {=LEFT(K4,2)&RIGHT(K4,2)+1} | Q4: {=LEFT(L4,2)&RIGHT(L4,2)+1} | R4: {=LEFT(M4,2)&RIGHT(M4,2)+1} | S4: {=LEFT(N4,2)&RIGHT(N4,2)+1} | T4: {=LEFT(O4,2)&RIGHT(O4,2)+1} | U4: {=LEFT(P4,2)&RIGHT(P4,2)+1} | ... AR4: {=LEFT(AM4,2)&RIGHT(AM4,2)+1} | AS4: Q223 | AT4: Q323 | AU4: {=LEFT(AP4,2)&RIGHT(AP4,2)+1} | AV4: {=LEFT(AQ4,2)&RIGHT(AQ4,2)+1} | AW4: {=LEFT(AR4,2)&RIGHT(AR4,2)+1} | AX4: Q224 | AY4: Q324 | AZ4: {=LEFT(AU4,2)&RIGHT(AU4,2)+1} | BA4: {=LEFT(AV4,2)&RIGHT(AV4,2)+1} | BB4: {=LEFT(AW4,2)&RIGHT(AW4,2)+1} | BC4: Q225 | BD4: Q325 | BE4: Q425 | BF4: {=LEFT(BA4,2)&RIGHT(BA4,2)+1} | BG4: Q126 | BH4: Q226 | BI4: Q326 | BJ4: Q426 | BK4: {=LEFT(BF4,2)&RIGHT(BF4,2)+1} | BL4: Q126 | BM4: Q226 | BN4: Q326 | BO4: Q426 | BP4: {=LEFT(BK4,2)&RIGHT(BK4,2)+1} | BQ4: Q126 | BR4: Q226 | BS4: Q326 | BT4: Q426 | BU4: {=LEFT(BP4,2)&RIGHT(BP4,2)+1} | BV4: Q126 | BW4: Q226 | BX4: Q326 | BY4: Q426 | BZ4: {=LEFT(BU4,2)&RIGHT(BU4,2)+1} | CA4: 0
H5: A | I5: A | J5: A | K5: A | L5: A | M5: A | N5: A | O5: A | P5: A | Q5: A | R5: A | S5: A | T5: A | U5: A | V5: A | W5: A | X5: A | Y5: A | Z5: A | AA5: A | AB5: A | AC5: A | AD5: A | AE5: A | AF5: A | AG5: A | AH5: A | AI5: A | AJ5: A | AK5: A | AL5: A | AM5: A | AN5: A | AO5: A | AP5: A | AQ5: A | AR5: A | AS5: A | AT5: A | AU5: A | AV5: A | AW5: A | AX5: A | AY5: A | AZ5: A | BA5: A | BB5: A | BC5: A | BD5: E | BE5: E | BF5: E | BG5: E | BH5: E | BI5: E | BJ5: E | BK5: E | BL5: E | BM5: E | BN5: E | BO5: E | BP5: E | BQ5: E | BR5: E | BS5: E | BT5: E | BU5: E | BV5: E | BW5: E | BX5: E | BY5: E | BZ5: E | CA5: {=BC269*CA4}
B6: Text_11 | I6: {=H3} | J6: {=I3} | K6: {=J3} | L6: {=K3} | M6: {=H3} | N6: {=M3} | O6: {=N3} | P6: {=O3} | Q6: {=P3} | R6: {=M3} | S6: {=R3} | T6: {=S3} | U6: {=T3} | V6: {=U3} | W6: {=R3} | X6: {=W3} | Y6: {=X3} | Z6: {=Y3} | AA6: {=Z3} | AB6: {=W3} | AC6: {=AB3} | AD6: {=AC3} | AE6: {=AD3} | AF6: {=AE3} | AG6: {=AB3} | AH6: {=AG3} | AI6: {=AH3} | AJ6: {=AI3} | AK6: {=AJ3} | AL6: {=AG3} | AM6: {=AL3} | AN6: {=AM3} | AO6: {=AN3} | AP6: {=AO3} | AQ6: {=AL3} | AR6: {=AQ7} | AS6: {=AR3} | AT6: {=AS3} | AU6: {=AT3} | AV6: {=AQ3} | AW6: {=AV7} | AZ6: {=AY3} | BA6: {=AV3}
B7: Text_12 | I7: {=I3} | J7: {=J3} | K7: {=K3} | L7: {=L3} | M7: {=M3} | N7: {=N3} | O7: {=O3} | P7: {=P3} | ... AW7: {=AW3} | AZ7: {=AZ3} | BA7: {=BA3}
B9: Text_13
B10: Text_14 | I10: 0 | J10: 0 | K10: 0 | L10: 0 | M10: {=AVERAGE(I10:L10)} | N10: 0 | O10: 0 | P10: 0 | Q10: 0 | R10: {=AVERAGE(N10:Q10)} | S10: 0 | T10: 0 | U10: 0 | V10: 0 | W10: {=AVERAGE(S10:V10)} | X10: 0 | Y10: 0 | Z10: 0 | AA10: 0 | AB10: {=AVERAGE(X10:AA10)} | AC10: 0 | AD10: 0 | AE10: 0 | AF10: 0 | AG10: {=AVERAGE(AC10:AF10)} | AH10: 0 | AI10: 0 | AJ10: 0 | AK10: 0 | AL10: {=AVERAGE(AH10:AK10)} | AM10: 0 | AN10: 0 | AO10: 0 | AP10: 0 | AQ10: {=AVERAGE(AM10:AP10)} | AR10: 0 | AS10: 0 | AT10: 0 | AU10: 0 | AV10: {=AVERAGE(AR10:AU10)} | AW10: 0 | AZ10: 0 | BA10: {=AVERAGE(AW10:AZ10)} | BF10: 0
B11: Text_15 | N11: {=N10/I10-1} | O11: {=O10/J10-1} | P11: {=P10/K10-1} | Q11: {=Q10/L10-1} | R11: {=R10/M10-1} | S11: {=S10/N10-1} | T11: {=T10/O10-1} | U11: {=U10/P10-1} | ... AW11: {=AW10/AR10-1} | AZ11: {=AZ10/AU10-1} | BA11: {=BA10/AV10-1} | BF11: {=BF10/BA10-1}
B12: Text_16 | I12: 0 | J12: 0 | K12: 0 | L12: 0 | M12: {=AVERAGE(I12:L12)} | N12: 0 | O12: 0 | P12: 0 | Q12: 0 | R12: {=AVERAGE(N12:Q12)} | S12: 0 | T12: 0 | U12: 0 | V12: 0 | W12: {=AVERAGE(S12:V12)} | X12: 0 | Y12: 0 | Z12: 0 | AA12: 0 | AB12: {=AVERAGE(X12:AA12)} | AC12: 0 | AD12: 0 | AE12: 0 | AF12: 0 | AG12: {=AVERAGE(AC12:AF12)} | AH12: 0 | AI12: 0 | AJ12: 0 | AK12: 0 | AL12: {=AVERAGE(AH12:AK12)} | AM12: 0 | AN12: 0 | AO12: 0 | AP12: 0 | AQ12: {=AVERAGE(AM12:AP12)} | AR12: 0 | AS12: 0 | AT12: 0 | AU12: 0 | AV12: {=AVERAGE(AR12:AU12)} | AW12: 0 | AZ12: 0 | BA12: {=AVERAGE(AW12:AZ12)} | BF12: 0
B13: Text_15 | N13: {=N12/I12-1} | O13: {=O12/J12-1} | P13: {=P12/K12-1} | Q13: {=Q12/L12-1} | R13: {=R12/M12-1} | S13: {=S12/N12-1} | T13: {=T12/O12-1} | U13: {=U12/P12-1} | ... AW13: {=AW12/AR12-1} | AZ13: {=AZ12/AU12-1} | BA13: {=BA12/AV12-1} | BF13: {=BF12/BA12-1}
B14: Text_17 | I14: 0 | J14: 0 | K14: 0 | L14: 0 | M14: {=AVERAGE(I14:L14)} | N14: 0 | O14: 0 | P14: 0 | Q14: 0 | R14: {=AVERAGE(N14:Q14)} | S14: 0 | T14: 0 | U14: 0 | V14: 0 | W14: {=AVERAGE(S14:V14)} | X14: 0 | Y14: 0 | Z14: 0 | AA14: 0 | AB14: {=AVERAGE(X14:AA14)} | AC14: 0 | AD14: 0 | AE14: 0 | AF14: 0 | AG14: {=AVERAGE(AC14:AF14)} | AH14: 0 | AI14: 0 | AJ14: 0 | AK14: 0 | AL14: {=AVERAGE(AH14:AK14)} | AM14: 0 | AN14: 0 | AO14: 0 | AP14: 0 | AQ14: {=AVERAGE(AM14:AP14)} | AR14: 0 | AS14: 0 | AT14: 0 | AU14: 0 | AV14: {=AVERAGE(AR14:AU14)} | AW14: 0 | AZ14: 0 | BA14: {=AVERAGE(AW14:AZ14)} | BF14: 0
B15: Text_15 | N15: {=N14/I14-1} | O15: {=O14/J14-1} | P15: {=P14/K14-1} | Q15: {=Q14/L14-1} | R15: {=R14/M14-1} | S15: {=S14/N14-1} | T15: {=T14/O14-1} | U15: {=U14/P14-1} | ... AW15: {=AW14/AR14-1} | AZ15: {=AZ14/AU14-1} | BA15: {=BA14/AV14-1} | BF15: {=BF14/BA14-1}
B16: Text_18 | I16: 0 | J16: 0 | K16: 0 | L16: 0 | M16: {=AVERAGE(I16:L16)} | N16: 0 | O16: 0 | P16: 0 | Q16: 0 | R16: {=AVERAGE(N16:Q16)} | S16: 0 | T16: 0 | U16: 0 | V16: 0 | W16: {=AVERAGE(S16:V16)} | X16: 0 | Y16: 0 | Z16: 0 | AA16: 0 | AB16: {=AVERAGE(X16:AA16)} | AC16: 0 | AD16: 0 | AE16: 0 | AF16: 0 | AG16: {=AVERAGE(AC16:AF16)} | AH16: 0 | AI16: 0 | AJ16: 0 | AK16: 0 | AL16: {=AVERAGE(AH16:AK16)} | AM16: 0 | AN16: 0 | AO16: 0 | AP16: 0 | AQ16: {=AVERAGE(AM16:AP16)} | AR16: 0 | AS16: 0 | AT16: 0 | AU16: 0 | AV16: {=AVERAGE(AR16:AU16)} | AW16: 0 | AZ16: 0 | BA16: {=AVERAGE(AW16:AZ16)} | BF16: 0
B17: Text_15 | N17: {=N16/I16-1} | O17: {=O16/J16-1} | P17: {=P16/K16-1} | Q17: {=Q16/L16-1} | R17: {=R16/M16-1} | S17: {=S16/N16-1} | T17: {=T16/O16-1} | U17: {=U16/P16-1} | ... AW17: {=AW16/AR16-1} | AZ17: {=AZ16/AU16-1} | BA17: {=BA16/AV16-1} | BF17: {=BF16/BA16-1}
B18: Text_19 | I18: 0 | J18: 0 | K18: 0 | L18: 0 | M18: {=AVERAGE(I18:L18)} | N18: 0 | O18: 0 | P18: 0 | Q18: 0 | R18: {=AVERAGE(N18:Q18)} | S18: 0 | T18: 0 | U18: 0 | V18: 0 | W18: {=AVERAGE(S18:V18)} | X18: 0 | Y18: 0 | Z18: 0 | AA18: 0 | AB18: {=AVERAGE(X18:AA18)} | AC18: 0 | AD18: 0 | AE18: 0 | AF18: 0 | AG18: {=AVERAGE(AC18:AF18)} | AH18: 0 | AI18: 0 | AJ18: 0 | AK18: 0 | AL18: {=AVERAGE(AH18:AK18)} | AM18: 0 | AN18: 0 | AO18: 0 | AP18: 0 | AQ18: {=AVERAGE(AM18:AP18)} | AR18: 0 | AS18: 0 | AT18: 0 | AU18: 0 | AV18: {=AVERAGE(AR18:AU18)} | AW18: 0 | AZ18: 0 | BA18: {=AVERAGE(AW18:AZ18)} | BF18: 0
B19: Text_15 | N19: {=N18/I18-1} | O19: {=O18/J18-1} | P19: {=P18/K18-1} | Q19: {=Q18/L18-1} | R19: {=R18/M18-1} | S19: {=S18/N18-1} | T19: {=T18/O18-1} | U19: {=U18/P18-1} | ... AW19: {=AW18/AR18-1} | AZ19: {=AZ18/AU18-1} | BA19: {=BA18/AV18-1} | BF19: {=BF18/BA18-1}
B20: Text_20 | I20: {=(I24*I11)+(I27*I13)+(I30*I17)+(I36*I19)+(I39*I15)} | J20: {=(J24*J11)+(J27*J13)+(J30*J17)+(J36*J19)+(J39*J15)} | K20: {=(K24*K11)+(K27*K13)+(K30*K17)+(K36*K19)+(K39*K15)} | L20: {=(L24*L11)+(L27*L13)+(L30*L17)+(L36*L19)+(L39*L15)} | M20: {=(M24*M11)+(M27*M13)+(M30*M17)+(M36*M19)+(M39*M15)} | N20: {=(N24*N11)+(N27*N13)+(N30*N17)+(N36*N19)+(N39*N15)} | O20: {=(O24*O11)+(O27*O13)+(O30*O17)+(O36*O19)+(O39*O15)} | P20: {=(P24*P11)+(P27*P13)+(P30*P17)+(P36*P19)+(P39*P15)} | ... AW20: {=(AW24*AW11)+(AW27*AW13)+(AW30*AW17)+(AW36*AW19)+(AW39*AW15)} | AZ20: {=(AZ24*AZ11)+(AZ27*AZ13)+(AZ30*AZ17)+(AZ36*AZ19)+(AZ39*AZ15)} | BA20: {=(BA24*BA11)+(BA27*BA13)+(BA30*BA17)+(BA36*BA19)+(BA39*BA15)} | BF20: {=($AV$24*BF11)+($AV$27*BF13)+($AV$30*BF17)+($AV$36*BF19)+($AV$39*BF15)}
B21: Text_21
B22: Text_22 | I22: 65.421334 | J22: 75.508198 | K22: 85.318336 | L22: 226.54938 | M22: 483.12747 | N22: 78.99202 | O22: 61.379564 | P22: 124.3981 | Q22: 134.10785 | R22: 349.79509 | S22: 168.01423 | T22: 54.082184 | U22: 167.29872 | V22: 238.95453 | W22: 684.83588 | X22: 314.51661 | Y22: 272.04437 | Z22: 210.01599 | AA22: 349.25423 | AB22: 1444.1767 | AC22: 376.55151 | AD22: 443.70355 | AE22: 412.21299 | AF22: 394.35517 | AG22: 1697.1038 | AH22: 411.31473 | AI22: 333.52596 | AJ22: 295.13006 | AK22: 573.10158 | AL22: 1766.6312 | AM22: 624.77229 | AN22: 612.25749 | AO22: 668.83675 | AP22: 657.9623 | AQ22: 2705.8741 | AR22: 723.26538 | AS22: 764.10419 | AT22: 524.84312 | AU22: 849.54591 | AV22: 3179.7015 | AW22: 906.47866 | AX22: {=AX24*AX$43} | AY22: {=AY24*AY$43} | AZ22: {=AZ24*AZ$43} | BA22: {=AZ22+AY22+AX22+AW22} | BB22: {=BB24*BB$43} | BC22: {=BC24*BC212} | BD22: {=BD24*BD43} | BE22: {=BE24*BE43} | BF22: {=BE22+BD22+BC22+BB22} | BG22: {=BG24*BG43} | BH22: {=BH24*BH43} | BI22: {=BI24*BI43} | BJ22: {=BJ24*BJ43} | BK22: {=BJ22+BI22+BH22+BG22} | BL22: {=BL24*BL43} | BM22: {=BM24*BM43} | BN22: {=BN24*BN43} | BO22: {=BO24*BO43} | BP22: {=BO22+BN22+BM22+BL22} | BQ22: {=BQ24*BQ43} | BR22: {=BR24*BR43} | BS22: {=BS24*BS43} | BT22: {=BT24*BT43} | BU22: {=BT22+BS22+BR22+BQ22} | BV22: {=BV24*BV43} | BW22: {=BW24*BW43} | BX22: {=BX24*BX43} | BY22: {=BY24*BY43} | BZ22: {=BY22+BX22+BW22+BV22} | CA22: Text_23
B23: Text_24 | N23: {=N22/I22-1} | O23: {=O22/J22-1} | P23: {=P22/K22-1} | Q23: {=Q22/L22-1} | R23: {=R22/M22-1} | S23: {=S22/N22-1} | T23: {=T22/O22-1} | U23: {=U22/P22-1} | ... BZ23: {=BZ22/BU22-1}
B24: Text_25 | I24: {=I22/I$43} | J24: {=J22/J$43} | K24: {=K22/K$43} | L24: {=L22/L$43} | M24: {=M22/M$43} | N24: {=N22/N$43} | O24: {=O22/O$43} | P24: {=P22/P$43} | ... AW24: {=AW22/AW$43} | AX24: 0.38296854 | AY24: 0.43766584 | AZ24: 0.45213563 | BA24: {=BA22/$BA$43} | BB24: 0.4328244 | BC24: 0.37302098 | BD24: 0.28296179 | BE24: 0.28452734 | BF24: {=BF22/BF43} | BG24: 0.27514694 | BH24: 0.29355586 | BI24: 0.27443873 | BJ24: 0.2541378 | BK24: {=BK22/BK43} | BL24: 0.23545195 | BM24: 0.24369941 | BN24: 0.24417278 | BO24: 0.25765354 | BP24: {=BP22/BP43} | BQ24: 0.23421843 | BR24: 0.24187452 | BS24: 0.22914792 | BT24: 0.21833422 | BU24: {=BU22/BU43} | BV24: 0.22625518 | BW24: 0.22764969 | BX24: 0.22179746 | BY24: 0.22794837 | BZ24: {=BZ22/BZ43}
B25: Text_26 | I25: 253.41652 | J25: 253.64969 | K25: 143.2958 | L25: 195.71463 | M25: 754.25161 | N25: 222.39437 | O25: 354.39472 | P25: 287.76425 | Q25: 184.33981 | R25: 1284.3384 | S25: 124.66387 | T25: 209.01973 | U25: 172.41814 | V25: 111.06993 | W25: 528.68527 | X25: 233.039 | Y25: 230.41558 | Z25: 322.86088 | AA25: 347.36224 | AB25: 1164.7292 | AC25: 438.32476 | AD25: 507.84135 | AE25: 298.90532 | AF25: 439.08372 | AG25: 1580.1852 | AH25: 414.68002 | AI25: 439.85846 | AJ25: 367.94138 | AK25: 455.0385 | AL25: 1501.5667 | AM25: 606.92393 | AN25: 875.12648 | AO25: 602.35026 | AP25: 499.07661 | AQ25: 2560.5601 | AR25: 711.29368 | AS25: 683.51947 | AT25: 412.54412 | AU25: 464.89649 | AV25: 2935.1157 | AW25: 378.66583 | AX25: {=AX27*AX$43} | AY25: {=AY27*AY$43} | AZ25: {=AZ27*AZ$43} | BA25: {=AZ25+AY25+AX25+AW25} | BB25: {=BB27*BB$43} | BC25: {=BC27*BC$43}
B26: Text_24 | N26: {=N25/I25-1} | O26: {=O25/J25-1} | P26: {=P25/K25-1} | Q26: {=Q25/L25-1} | R26: {=R25/M25-1} | S26: {=S25/N25-1} | T26: {=T25/O25-1} | U26: {=U25/P25-1} | ... BC26: {=BC25/AX25-1}
B27: Text_25 | I27: {=I25/I$43} | J27: {=J25/J$43} | K27: {=K25/K$43} | L27: {=L25/L$43} | M27: {=M25/M$43} | N27: {=N25/N$43} | O27: {=O25/O$43} | P27: {=P25/P$43} | ... AW27: {=AW25/AW$43} | AX27: 0.15037581 | AY27: 0.18487246 | AZ27: 0.19636346 | BA27: {=BA25/$BA$43} | BB27: 0.17006468 | BC27: 0.3078813
B28: Text_27 | I28: 66.142052 | J28: 79.789088 | K28: 77.624271 | L28: 119.04293 | M28: 299.75236 | N28: 141.00937 | O28: 96.949781 | P28: 131.65488 | Q28: 269.53653 | R28: 800.46412 | S28: 246.06335 | T28: 231.80651 | U28: 312.73701 | V28: 381.77751 | W28: 1056.9954 | X28: 164.07019 | Y28: 140.25493 | Z28: 175.86936 | AA28: 116.91171 | AB28: 553.20033 | AC28: 208.35012 | AD28: 190.80909 | AE28: 303.31156 | AF28: 256.28167 | AG28: 1116.6094 | AH28: 171.39833 | AI28: 303.21126 | AJ28: 456.45579 | AK28: 259.41329 | AL28: 1436.0291 | AM28: 201.70763 | AN28: 330.96143 | AO28: 428.04111 | AP28: 420.98268 | AQ28: 1268.0287 | AR28: 439.87532 | AS28: 564.16314 | AT28: 542.93738 | AU28: 366.87212 | AV28: 1775.1932 | AW28: 182.37251 | AX28: {=AX30*AX$43} | AY28: {=AY30*AY$43} | AZ28: {=AZ30*AZ$43} | BA28: {=AZ28+AY28+AX28+AW28} | BB28: {=BB30*BB$43} | BC28: {=BC30*BC$43}
B29: Text_24 | N29: {=N28/I28-1} | O29: {=O28/J28-1} | P29: {=P28/K28-1} | Q29: {=Q28/L28-1} | R29: {=R28/M28-1} | S29: {=S28/N28-1} | T29: {=T28/O28-1} | U29: {=U28/P28-1} | ... BC29: {=BC28/AX28-1}
B30: Text_25 | I30: {=I28/I$43} | J30: {=J28/J$43} | K30: {=K28/K$43} | L30: {=L28/L$43} | M30: {=M28/M$43} | N30: {=N28/N$43} | O30: {=O28/O$43} | P30: {=P28/P$43} | ... AW30: {=AW28/AW$43} | AX30: 0.1267951 | AY30: 0.094528072 | AZ30: 0.067740789 | BA30: {=BA28/$BA$43} | BB30: 0.081706496 | BC30: 0.12507556
B31: Text_28 | I31: 111.61935 | J31: 118.11343 | K31: 146.94176 | L31: 110.12735 | M31: 604.16799 | N31: 101.24315 | O31: 161.31643 | P31: 110.40501 | Q31: 154.66538 | R31: 570.2961 | S31: 149.7806 | T31: 172.11885 | U31: 126.18077 | V31: 108.38776 | W31: 412.10116 | X31: 88.305992 | Y31: 174.04427 | Z31: 163.50025 | AA31: 150.59816 | AB31: 501.37076 | AC31: 195.7608 | AD31: 133.16803 | AE31: 135.38417 | AF31: 163.69309 | AG31: 718.17063 | AH31: 179.53587 | AI31: 190.94293 | AJ31: 195.68623 | AK31: 189.54136 | AL31: 721.84165 | AM31: 206.03675 | AN31: 299.21308 | AO31: 260.83797 | AP31: 264.35159 | AQ31: 973.28882 | AR31: 205.34608 | AS31: 347.24068 | AT31: 308.57957 | AU31: 281.11356 | AV31: 1492.399 | AW31: 229.446 | AX31: {=AX33*AX$43} | AY31: {=AY33*AY$43} | AZ31: {=AZ33*AZ$43} | BA31: {=AZ31+AY31+AX31+AW31} | BB31: {=BB33*BB$43} | BC31: {=BC33*BC$43} | CA31: Text_29
B32: Text_24 | N32: {=N31/I31-1} | O32: {=O31/J31-1} | P32: {=P31/K31-1} | Q32: {=Q31/L31-1} | R32: {=R31/M31-1} | S32: {=S31/N31-1} | T32: {=T31/O31-1} | U32: {=U31/P31-1} | ... BC32: {=BC31/AX31-1}
B33: Text_25 | I33: {=I31/I$43} | J33: {=J31/J$43} | K33: {=K31/K$43} | L33: {=L31/L$43} | M33: {=M31/M$43} | N33: {=N31/N$43} | O33: {=O31/O$43} | P33: {=P31/P$43} | ... AW33: {=AW31/AW$43} | AX33: 0.11575002 | AY33: 0.10174852 | AZ33: 0.12471698 | BA33: {=BA31/$BA$43} | BB33: 0.18006329 | BC33: 0.090922847
B34: Text_30 | I34: 71.403653 | J34: 95.822356 | K34: 157.07024 | L34: 108.78098 | M34: 359.69342 | N34: 110.88127 | O34: 59.091138 | P34: 101.95511 | Q34: 108.56278 | R34: 409.48248 | S34: 138.82968 | T34: 124.76644 | U34: 233.17147 | V34: 134.12804 | W34: 757.51513 | X34: 160.72067 | Y34: 205.73964 | Z34: 134.05914 | AA34: 114.10212 | AB34: 663.20746 | AC34: 196.4862 | AD34: 170.28686 | AE34: 160.19489 | AF34: 137.14568 | AG34: 735.09352 | AH34: 173.99129 | AI34: 138.48663 | AJ34: 169.80766 | AK34: 184.23238 | AL34: 557.03173 | AM34: 167.92931 | AN34: 216.62061 | AO34: 150.54555 | AP34: 241.44387 | AQ34: 774.03956 | AR34: 205.70414 | AS34: 247.47489 | AT34: 246.02668 | AU34: 207.98211 | AV34: 1018.4024 | AW34: 279.31638 | AX34: {=AX36*AX$43} | AY34: {=AY36*AY$43} | AZ34: {=AZ36*AZ$43} | BA34: {=AZ34+AY34+AX34+AW34} | BB34: {=BB36*BB$43} | BC34: {=BC36*BC$43}
B35: Text_24 | N35: {=N34/I34-1} | O35: {=O34/J34-1} | P35: {=P34/K34-1} | Q35: {=Q34/L34-1} | R35: {=R34/M34-1} | S35: {=S34/N34-1} | T35: {=T34/O34-1} | U35: {=U34/P34-1} | ... BC35: {=BC34/AX34-1}
B36: Text_25 | I36: {=I34/I$43} | J36: {=J34/J$43} | K36: {=K34/K$43} | L36: {=L34/L$43} | M36: {=M34/M$43} | N36: {=N34/N$43} | O36: {=O34/O$43} | P36: {=P34/P$43} | ... AW36: {=AW34/AW$43} | AX36: 0.12018148 | AY36: 0.11002224 | AZ36: 0.072784088 | BA36: {=BA34/$BA$43} | BB36: 0.071399663 | BC36: 0.071885024
B37: Text_31 | I37: 44.560462 | J37: 47.783348 | K37: 35.392571 | L37: 46.475905 | M37: 140.66198 | N37: 35.939163 | O37: 76.095378 | P37: 90.708365 | Q37: 44.269477 | R37: 241.26577 | S37: 86.539013 | T37: 66.728736 | U37: 43.226824 | V37: 92.781139 | W37: 284.0565 | X37: 60.97772 | Y37: 81.335283 | Z37: 84.267636 | AA37: 68.764017 | AB37: 320.96206 | AC37: 47.159349 | AD37: 74.326011 | AE37: 72.091157 | AF37: 89.003428 | AG37: 322.69676 | AH37: 83.888373 | AI37: 117.90588 | AJ37: 90.776693 | AK37: 107.34685 | AL37: 426.76915 | AM37: 75.712745 | AN37: 160.66393 | AO37: 133.19357 | AP37: 161.1686 | AQ37: 719.54916 | AR37: 185.4339 | AS37: 182.90999 | AT37: 210.96138 | AU37: 121.07857 | AV37: 588.36487 | AW37: 151.02453 | AX37: {=AX39*AX$43} | AY37: {=AY39*AY$43} | AZ37: {=AZ39*AZ$43} | BA37: {=AZ37+AY37+AX37+AW37} | BB37: {=BB39*BB$43} | BC37: {=BC39*BC$43}
B38: Text_24 | N38: {=N37/I37-1} | O38: {=O37/J37-1} | P38: {=P37/K37-1} | Q38: {=Q37/L37-1} | R38: {=R37/M37-1} | S38: {=S37/N37-1} | T38: {=T37/O37-1} | U38: {=U37/P37-1} | ... BC38: {=BC37/AX37-1}
B39: Text_25 | I39: {=I37/I$43} | J39: {=J37/J$43} | K39: {=K37/K$43} | L39: {=L37/L$43} | M39: {=M37/M$43} | N39: {=N37/N$43} | O39: {=O37/O$43} | P39: {=P37/P$43} | ... AW39: {=AW37/AW$43} | AX39: 0.050328178 | AY39: 0.061716767 | AZ39: 0.051067983 | BA39: {=BA37/$BA$43} | BB39: 0.048532893 | BC39: 0.042425948
B40: Text_32 | I40: 20.961339 | J40: 20.846594 | K40: 65.025578 | L40: 54.860076 | M40: 142.47917 | N40: 27.616712 | O40: 62.18612 | P40: 24.175139 | Q40: 18.469082 | R40: 112.53015 | S40: 23.52144 | T40: 41.604061 | U40: 44.834218 | V40: 38.038938 | W40: 121.78599 | X40: 35.691899 | Y40: 45.021144 | Z40: 34.947694 | AA40: 56.325168 | AB40: 172.09271 | AC40: 44.36735 | AD40: 47.7306 | AE40: 34.949271 | AF40: 27.729111 | AG40: 167.63304 | AH40: 77.02751 | AI40: 75.451094 | AJ40: 57.548157 | AK40: 33.31734 | AL40: 195.1208 | AM40: 88.101979 | AN40: 57.211576 | AO40: 71.01603 | AP40: 87.739023 | AQ40: 312.13511 | AR40: 104.1022 | AS40: 144.05921 | AT40: 71.759588 | AU40: 81.767248 | AV40: 487.63486 | AW40: 91.510129 | AX40: {=AX42*AX$43} | AY40: {=AY42*AY$43} | AZ40: {=AZ42*AZ$43} | BA40: {=AZ40+AY40+AX40+AW40} | BB40: {=BB42*BB$43} | BC40: {=BC42*BC$43}
B41: Text_24 | N41: {=N40/I40-1} | O41: {=O40/J40-1} | P41: {=P40/K40-1} | Q41: {=Q40/L40-1} | R41: {=R40/M40-1} | S41: {=S40/N40-1} | T41: {=T40/O40-1} | U41: {=U40/P40-1} | ... BC41: {=BC40/AX40-1}
B42: Text_25 | I42: {=I40/I$43} | J42: {=J40/J$43} | K42: {=K40/K$43} | L42: {=L40/L$43} | M42: {=M40/M$43} | N42: {=N40/N$43} | O42: {=O40/O$43} | P42: {=P40/P$43} | ... AW42: {=AW40/AW$43} | AX42: 0.042459683 | AY42: 0.04216187 | AZ42: 0.047971941 | BA42: {=BA40/$BA$43} | BB42: 0.03770326 | BC42: 0.028403112
...

Sheet Sheet_3
B2: Text_362 | E2: {=IF(L10="FCF",(($E$6*O16)+((365-$E$6)*R16))/365,(($E$6*O14)+((365-$E$6)*R14))/365)}
B3: Text_363 | E3: {=IF(L10="FCF",(($E$6*R16)+((365-$E$6)*U16))/365,(($E$6*R14)+((365-$E$6)*U14))/365)}
B4: Text_364 | E4: {=TODAY()}
B5: Text_365 | E5: 46022
B6: Text_366 | E6: {=E5-E4}
B9: Text_361
B10: Text_367 | E10: Text_368 | F10: 0.029596141 | H10: Text_369 | I10: {='Valuation'!Y54} | K10: Text_370 | L10: Text_371
B12: Text_372 | AC12: Text_373
B14: Text_374 | E14: Text_375 | F14: {='Valuation'!N45} | H14: Text_376 | I14: {='Valuation'!N46} | K14: Text_377 | L14: {='Valuation'!N47} | N14: Text_378 | O14: {='Valuation'!N48} | Q14: Text_379 | R14: {='Valuation'!N49} | T14: Text_380 | U14: {='Valuation'!N50} | W14: Text_381 | Z14: Text_382 | AD14: Text_383
AD15: Text_8
B16: Text_384 | E16: Text_385 | F16: {='Valuation'!N55} | H16: Text_386 | I16: {='Valuation'!N56} | K16: Text_387 | L16: {='Valuation'!N57} | N16: Text_388 | O16: {='Valuation'!N58} | Q16: Text_389 | R16: {='Valuation'!N59} | T16: Text_390 | U16: {='Valuation'!N60} | W16: Text_391 | Z16: Text_392
AD17: Text_393
B18: Text_394 | E18: Text_395 | F18: {='Model'!AQ358} | H18: Text_396 | I18: {='Model'!AV358} | K18: Text_397 | L18: {='Model'!BA358} | N18: Text_398 | O18: {='Model'!BF358} | Q18: Text_399 | R18: {='Model'!BK358} | T18: Text_400 | W18: Text_401 | Z18: Text_402 | AD18: Text_403
B21: Text_404 | E21: Text_405 | F21: {='Model'!AQ357} | H21: Text_406 | I21: {='Model'!AV357} | K21: Text_407 | L21: {='Model'!BA357} | N21: Text_408 | O21: {='Model'!BF357} | Q21: Text_409 | R21: {='Model'!BK357} | T21: Text_410 | W21: Text_411 | Z21: Text_412 | AC21: Text_413
AD22: Text_383 | AE22: {=E2*I10}
B23: Text_414 | E23: Text_415 | H23: Text_416 | K23: Text_417 | N23: Text_418 | Q23: Text_419 | T23: Text_420 | W23: Text_421 | Z23: Text_422 | AD23: Text_8 | AE23: {=I10*E3}
B25: Text_423 | E25: Text_424 | H25: Text_425 | K25: Text_426 | N25: Text_427 | Q25: Text_428 | T25: Text_429 | W25: Text_430 | Z25: Text_431
B27: Text_432 | E27: Text_433 | H27: Text_434 | K27: Text_435 | N27: Text_436 | Q27: Text_437 | T27: Text_438 | W27: Text_439 | Z27: Text_440
B29: Text_441
B31: Text_442 | C31: {='Valuation'!AY51} | E31: Text_443 | F31: {='Valuation'!AY48}
B33: Text_444 | C33: {='Valuation'!AR59} | E33: Text_445 | F33: {='Valuation'!AR60} | H33: Text_446 | I33: {='Valuation'!AR61} | K33: Text_447 | L33: {='Valuation'!AR62} | N33: Text_448 | O33: {='Valuation'!AR63} | Q33: Text_449
B35: Text_450
B37: Text_451 | C37: {='Valuation'!AL51} | E37: Text_452 | F37: {='Valuation'!AL48}
B39: Text_453 | C39: {='Valuation'!AE59} | E39: Text_454 | F39: {='Valuation'!AE60} | H39: Text_455 | I39: {='Valuation'!AE61} | K39: Text_456 | L39: {='Valuation'!AE62} | N39: Text_457 | O39: {='Valuation'!AE63} | Q39: Text_458
B41: Text_459
B43: Text_460 | E43: Text_461 | H43: Text_380 | K43: Text_462 | N43: Text_463 | O43: {='Valuation'!W61} | Q43: Text_464 | R43: {='Valuation'!W63} | T43: Text_465 | U43: {='Valuation'!W62}
B45: Text_466 | C45: {='Valuation'!N14*100} | E45: Text_467 | F45: {='Valuation'!N26*100} | H45: Text_381 | I45: {='Valuation'!N51} | K45: Text_468 | L45: {='Valuation'!R56}
B47: Text_469 | C47: {='Valuation'!N14*100} | E47: Text_470 | F47: {='Valuation'!N26*100} | H47: Text_471 | I47: {='Valuation'!N52} | K47: Text_472 | L47: {='Valuation'!R56}
B51: Text_459 | C51: {=_xlfn.IFERROR((C54^(1/((DAYS360(TODAY(),"31/12/2028"))/360))-1)+C52,"")}
B52: Text_473 | C52: {='Model'!BA412}
B53: Text_474 | C53: {='Model'!CA4}
B54: Text_475 | C54: {=_xlfn.IFERROR((C55/C53),"")}
B55: Text_476 | C55: {=_xlfn.IFERROR(C56*I47,"")}
B56: Text_477 | C56: {=_xlfn.IFERROR(C57*L47,"")}
B57: Text_478 | C57: 18.17473

Sheet Sheet_4
B2: Text_480 | G2: Text_132 | R2: Text_481
B3: Text_229 | C3: {='Model'!CA4} | E3: {='Model'!CA2} | N3: Text_482 | Q3: Text_229 | R3: {='Model'!CA4} | S3: Text_483 | AB3: Text_482 | AD3: Text_229 | AE3: {=C3} | AF3: Text_484 | AO3: Text_482 | AQ3: Text_229 | AR3: {=AE3} | AS3: Text_485 | BB3: Text_482
B4: Text_486 | D4: 1768.3408 | E4: 2160.4171 | F4: 2407.8032 | G4: 1700.8519 | H4: 1625.9358 | I4: Text_487 | J4: Text_488 | K4: Text_489 | L4: Text_490 | M4: Text_491 | N4: Text_492 | Q4: Text_486 | S4: 1967.3083 | T4: 1692.5155 | U4: 2223.9926 | V4: 2359.6186 | W4: Text_487 | X4: Text_488 | Y4: Text_489 | Z4: Text_490 | AA4: Text_491 | AB4: Text_492 | AD4: Text_486 | AF4: 1967.6626 | AG4: 1826.846 | AH4: 1969.9192 | AI4: 2204.9034 | AJ4: Text_487 | AK4: Text_488 | AL4: Text_489 | AM4: Text_490 | AN4: Text_491 | AO4: Text_492 | AQ4: Text_486 | AS4: 1624.1194 | AT4: 2094.3504 | AU4: 2114.6756 | AV4: 2135.4724 | AW4: Text_487 | AX4: Text_488 | AY4: Text_489 | AZ4: Text_490 | BA4: Text_491 | BB4: Text_492
B5: Text_493 | D5: 44012 | E5: 44377 | F5: {=E5+365} | G5: {=F5+365} | H5: {=G5+366} | I5: {=H5+365} | J5: {=I5+365} | K5: {=J5+365} | L5: {=K5+365} | M5: {=L5+365} | Q5: Text_493 | S5: 44377 | T5: 44742 | U5: 45107 | V5: 45473 | W5: 45838 | X5: 46203 | Y5: 46568 | Z5: {=Y5+365} | AA5: {=Z5+365} | AD5: Text_493 | AF5: 44377 | AG5: 44742 | AH5: 45107 | AI5: 45473 | AJ5: 45838 | AK5: 46203 | AL5: 46568 | AM5: {=AL5+365} | AN5: {=AM5+365} | AQ5: Text_493 | AS5: 44469 | AT5: 44742 | AU5: 45107 | AV5: 45473 | AW5: 45838 | AX5: 46203 | AY5: 46568 | AZ5: {=AY5+365} | BA5: {=AZ5+365}
AQ6: Text_494 | AW6: {=AW14/$W$14-1} | AX6: {=AX14/X$14-1} | AY6: {=AY14/Y$14-1} | AZ6: {=AZ14/Z$14-1} | BA6: {=BA14/AA$14-1}
B7: Text_495 | D7: {='Model'!AG101} | E7: {='Model'!AL101} | F7: {='Model'!AQ101} | G7: {='Model'!AV101} | H7: {='Model'!BA101} | I7: {='Model'!BF101} | J7: {='Model'!BK101} | K7: {='Model'!BP101} | L7: {='Model'!BU101} | M7: {='Model'!BZ101} | N7: {=(M7/H7)^(1/5)-1} | Q7: Text_495 | S7: 81434.098 | T7: 106049.98 | U7: 82783.967 | V7: 83942.454 | W7: 116271.76 | X7: 126689.76 | Y7: 96537.758 | Z7: 121865.55 | AA7: 134016.17 | AB7: {=(AA7/V7)^(1/5)-1} | AD7: Text_495 | AF7: 82479.592 | AG7: 87822.051 | AH7: 81641.391 | AI7: 93853.628 | AJ7: {=AI7*(1+AJ8)} | AK7: {=AJ7*(1+AK8)} | AL7: {=AK7*(1+AL8)} | AM7: {=AL7*(1+AM8)} | AN7: {=AM7*(1+AN8)} | AO7: {=(AN7/AI7)^(1/5)-1} | AQ7: Text_495 | AU7: 108170.34 | AV7: 99494.571 | AW7: {=AV7*(1+AW8)} | AX7: {=AW7*(1+AX8)} | AY7: {=AX7*(1+AY8)} | AZ7: {=AY7*(1+AZ8)} | BA7: {=AZ7*(1+BA8)} | BB7: {=(BA7/AV7)^(1/5)-1}
B8: Text_15 | E8: {=E7/D7-1} | F8: {=F7/E7-1} | G8: {=G7/F7-1} | H8: {=H7/G7-1} | I8: {=I7/H7-1} | J8: {=J7/I7-1} | K8: {=K7/J7-1} | L8: {=L7/K7-1} | M8: {=M7/L7-1} | Q8: Text_15 | T8: 0.41592535 | U8: 0.012294101 | V8: -0.037896229 | W8: 0.061317379 | X8: 0.15069115 | Y8: 0.037897424 | Z8: 0.13816351 | AA8: 0.11726285 | AD8: Text_15 | AG8: 0.39030756 | AH8: 0.013224055 | AI8: {=AI7/AH7-1} | AJ8: 0.13420995 | AK8: 0.1341239 | AL8: 0.13037178 | AM8: 0.12251995 | AN8: 0.12776596 | AQ8: Text_15 | AT8: -0.01525234 | AU8: 0.013167917 | AV8: {=AI8} | AW8: -0.050255546 | AX8: 0.077534437 | AY8: 0.049122993 | AZ8: 0.084217025 | BA8: 0.081775606
B9: Text_496 | G9: {='Model'!AV22} | H9: {='Model'!BA22} | I9: {='Model'!BF22} | J9: {='Model'!BK22} | K9: {='Model'!BP22} | L9: {='Model'!BU22} | M9: {='Model'!BZ22} | N9: {=(M9/H9)^(1/5)-1} | Q9: Text_496 | U9: 3197.0694 | V9: 4095.4393 | W9: 4339.8071 | X9: 3187.3033 | Y9: 3746.6701 | Z9: 3544.0407 | AA9: 3865.766 | AB9: {=(AA9/V9)^(1/5)-1} | AD9: Text_496 | AH9: 3038.7123 | AI9: {=V9} | AJ9: {=AI9*(1+AJ10)} | AK9: {=AJ9*(1+AK10)} | AL9: {=AK9*(1+AL10)} | AM9: {=AL9*(1+AM10)} | AN9: {=AM9*(1+AN10)} | AO9: {=(AN9/AI9)^(1/5)-1} | AQ9: Text_496 | AU9: 3367.8469 | AV9: {=AI9} | AW9: {=AV9*(1+AW10)} | AX9: {=AW9*(1+AX10)} | AY9: {=AX9*(1+AY10)} | AZ9: {=AY9*(1+AZ10)} | BA9: {=AZ9*(1+BA10)} | BB9: {=(BA9/AV9)^(1/5)-1}
B10: Text_15 | H10: {=H9/G9-1} | I10: {=I9/H9-1} | J10: {=J9/I9-1} | K10: {=K9/J9-1} | L10: {=L9/K9-1} | M10: {=M9/L9-1} | Q10: Text_15 | V10: 0.42838258 | W10: -0.011683548 | X10: -0.13693147 | Y10: -0.022924787 | Z10: 0.050731671 | AA10: 0.081874454 | AD10: Text_15 | AI10: {=AI9/AH9-1} | AJ10: -0.10003508 | AK10: 0 | AL10: 0.099881276 | AM10: 0.10569481 | AN10: 0.094738576 | AQ10: Text_15 | AV10: {=AV9/AU9-1} | AW10: -0.41410351 | AX10: -0.049397807 | AY10: -0.051034491 | AZ10: -0.048401577 | BA10: -0.047729948
B11: Text_497 | G11: {=G9/G14} | H11: {=H9/H14} | I11: {=I9/I14} | J11: {=J9/J14} | K11: {=K9/K14} | L11: {=L9/L14} | M11: {=M9/M14} | Q11: Text_497 | U11: 0.26082455 | V11: 0.40071813 | W11: 0.32655487 | X11: 0.28086502 | Y11: 0.26272302 | Z11: 0.23963319 | AA11: 0.22543061 | AD11: Text_497 | AH11: 0.25900215 | AI11: {=AI9/AI14} | AJ11: {=AJ9/AJ14} | AK11: {=AK9/AK14} | AL11: {=AL9/AL14} | AM11: {=AM9/AM14} | AN11: {=AN9/AN14} | AQ11: Text_497 | AU11: 0.26551344 | AV11: {=AV9/AV14} | AW11: {=AW9/AW14} | AX11: {=AX9/AX14} | AY11: {=AY9/AY14} | AZ11: {=AZ9/AZ14} | BA11: {=BA9/BA14}
B12: Text_498 | G12: {=G14-G9} | H12: {=H14-H9} | I12: {=I14-I9} | J12: {=J14-J9} | K12: {=K14-K9} | L12: {=L14-L9} | M12: {=M14-M9} | N12: {=(M12/H12)^(1/5)-1} | Q12: Text_498 | U12: 7048.2491 | V12: 5078.2098 | W12: 8025.1206 | X12: 9483.4089 | Y12: 9791.8337 | Z12: 11504.077 | AA12: 15871.923 | AB12: {=(AA12/V12)^(1/5)-1} | AD12: Text_498 | AH12: 8511.3743 | AI12: {=AI14-AI9} | AJ12: {=AI12*(1+AJ13)} | AK12: {=AJ12*(1+AK13)} | AL12: {=AK12*(1+AL13)} | AM12: {=AL12*(1+AM13)} | AN12: {=AM12*(1+AN13)} | AO12: {=(AN12/AI12)^(1/5)-1} | AQ12: Text_498 | AU12: 7042.1125 | AV12: {=AV14-AV9} | AW12: {=AV12*(1+AW13)} | AX12: {=AW12*(1+AX13)} | AY12: {=AX12*(1+AY13)} | AZ12: {=AY12*(1+AZ13)} | BA12: {=AZ12*(1+BA13)} | BB12: {=(BA12/AV12)^(1/5)-1}
B13: Text_15 | H13: {=H12/G12-1} | I13: {=I12/H12-1} | J13: {=J12/I12-1} | K13: {=K12/J12-1} | L13: {=L12/K12-1} | M13: {=M12/L12-1} | Q13: Text_15 | V13: -0.27470572 | W13: 0.43874257 | X13: 0.16816223 | Y13: 0.1086442 | Z13: 0.17654269 | AA13: 0.15681312 | AD13: Text_15 | AI13: {=AI12/AH12-1} | AJ13: 0.57759676 | AK13: 0.18940181 | AL13: 0.14785461 | AM13: 0.15106742 | AN13: 0.15006265 | AQ13: Text_15 | AV13: {=AV12/AU12-1} | AW13: 0.28775452 | AX13: 0.052392112 | AY13: 0.051179605 | AZ13: 0.13585708 | BA13: 0.13621858
B14: Text_499 | D14: {='Model'!AG212} | E14: {='Model'!AL212} | F14: {='Model'!AQ212} | G14: {='Model'!AV212} | H14: {='Model'!BA212} | I14: {='Model'!BF212} | J14: {='Model'!BK212} | K14: {='Model'!BP212} | L14: {='Model'!BU212} | M14: {='Model'!BZ212} | N14: {=(M14/H14)^(1/5)-1} | Q14: Text_499 | S14: 7606.0572 | T14: 8987.8891 | U14: 10960.178 | V14: 8480.8894 | W14: 12942.736 | X14: 11240.088 | Y14: 14922.915 | Z14: 14152.074 | AA14: 15233.657 | AB14: {=(AA14/V14)^(1/5)-1} | AD14: Text_499 | AF14: 5992.411 | AG14: 7376.8469 | AH14: 11414.417 | AI14: 10724.329 | AJ14: {=AJ12+AJ9} | AK14: {=AK12+AK9} | AL14: {=AL12+AL9} | AM14: {=AM12+AM9} | AN14: {=AN12+AN9} | AO14: {=(AN14/AI14)^(1/5)-1} | AQ14: Text_499 | AS14: 6960.062 | AT14: 7964.0885 | AU14: 8747.6412 | AV14: 7924.826 | AW14: {=AW12+AW9} | AX14: {=AX12+AX9} | AY14: {=AY12+AY9} | AZ14: {=AZ12+AZ9} | BA14: {=BA12+BA9} | BB14: {=(BA14/AV14)^(1/5)-1}
B15: Text_15 | E15: {=E14/D14-1} | F15: {=F14/E14-1} | G15: {=G14/F14-1} | H15: {=H14/G14-1} | I15: {=I14/H14-1} | J15: {=J14/I14-1} | K15: {=K14/J14-1} | L15: {=L14/K14-1} | M15: {=M14/L14-1} | Q15: Text_15 | T15: 0.31666927 | U15: 0.14666887 | V15: -0.062725799 | W15: 0.22859803 | X15: 0.062021405 | Y15: 0.071255677 | Z15: 0.14622792 | AA15: 0.13529938 | AD15: Text_15 | AF15: 0.18506119 | AG15: 0.31189582 | AH15: 0.13737857 | AI15: {=AI14/AH14-1} | AJ15: {=AJ14/AI14-1} | AK15: {=AK14/AJ14-1} | AL15: {=AL14/AK14-1} | AM15: {=AM14/AL14-1} | AN15: {=AN14/AM14-1} | AQ15: Text_15 | AS15: 0.18477642 | AT15: 0.31904706 | AU15: 0.14795152 | AV15: -0.066165483 | AW15: {=AW14/AV14-1} | AX15: {=AX14/AW14-1} | AY15: {=AY14/AX14-1} | AZ15: {=AZ14/AY14-1} | BA15: {=BA14/AZ14-1}
B16: Text_500 | D16: {='Model'!AG217} | E16: {='Model'!AL217} | F16: {='Model'!AQ217} | G16: {='Model'!AV217} | H16: {='Model'!BA217} | I16: {='Model'!BF217} | J16: {='Model'!BK217} | K16: {='Model'!BP217} | L16: {='Model'!BU217} | M16: {='Model'!BZ217} | Q16: Text_500 | S16: 4402.7258 | T16: 5593.562 | U16: 6283.8976 | V16: 6169.9455 | W16: 8068.0711 | X16: 8649.3239 | Y16: 7495.8369 | Z16: 9927.7175 | AA16: 10898.541 | AD16: Text_500 | AF16: 4942.8017 | AG16: 6092.8705 | AH16: 6551.8159 | AI16: 5136.7011 | AJ16: 1252.3168 | AK16: 1139.9564 | AL16: 1377.894 | AM16: 1264.164 | AN16: 1589.2586 | AQ16: Text_500 | AS16: 3798.9773 | AT16: 5538.1868 | AU16: 7491.3713 | AV16: 5352.6251 | AW16: 1205.2966 | AX16: 1302.5973 | AY16: 1189.7797 | AZ16: 1646.4632 | BA16: 1219.8006
B17: Text_501 | D17: {=D16/D14} | E17: {=E16/E14} | F17: {=F16/F14} | G17: {=G16/G14} | H17: {=H16/H14} | I17: {=I16/I14} | J17: {=J16/J14} | K17: {=K16/K14} | ... M17: {=M16/M14} | Q17: Text_501 | S17: 0.62005695 | T17: 0.63346562 | U17: 0.62675688 | V17: 0.63411277 | W17: 0.59776576 | X17: 0.58005181 | Y17: 0.64166307 | Z17: 0.62857362 | AA17: 0.6562481 | AD17: Text_501 | AF17: 0.6488548 | AG17: 0.65714705 | AH17: 0.61498063 | AI17: 0.60495749 | AJ17: 0.64410214 | AK17: 0.62094118 | AL17: 0.60101466 | AM17: 0.65981782 | AN17: 0.66476255 | AQ17: Text_501 | AS17: 0.61939782 | AT17: 0.59283206 | AU17: 0.60698898 | AV17: 0.64372072 | AW17: 0.65321332 | AX17: 0.59740801 | AY17: 0.5879722 | AZ17: 0.66799932 | BA17: 0.61873951
B18: Text_502 | D18: {='Model'!AG230} | E18: {='Model'!AL230} | F18: {='Model'!AQ230} | G18: {='Model'!AV230} | H18: {='Model'!BA230} | I18: {='Model'!BF230} | J18: {='Model'!BK230} | K18: {='Model'!BP230} | L18: {='Model'!BU230} | M18: {='Model'!BZ230} | Q18: Text_502 | S18: 3089.1617 | T18: 5053.2864 | U18: 3905.6618 | V18: 4553.3612 | W18: 4597.221 | X18: 5646.2479 | Y18: 7213.0375 | Z18: 7227.5706 | AA18: 10193.87 | AD18: Text_502 | AF18: 3110.1855 | AG18: 3951.8993 | AH18: 4195.8541 | AI18: 4041.3459 | AJ18: 1196.592 | AK18: 1175.3171 | AL18: 1480.5573 | AM18: 1540.6911 | AN18: 1703.3991 | AQ18: Text_502 | AS18: 3228.8902 | AT18: 4611.8144 | AU18: 3795.666 | AV18: 3812.926 | AW18: 1342.4259 | AX18: 1411.2514 | AY18: 1252.9599 | AZ18: 1752.3042 | BA18: 1732.5068
B19: Text_503 | D19: {='Model'!AG238} | E19: {='Model'!AL238} | F19: {='Model'!AQ238} | G19: {='Model'!AV238} | H19: {='Model'!BA238} | I19: {='Model'!BF238} | J19: {='Model'!BK238} | K19: {='Model'!BP238} | L19: {='Model'!BU238} | M19: {='Model'!BZ238} | N19: {=(M19/H19)^(1/5)-1} | Q19: Text_503 | S19: 2757.4629 | T19: 3217.9264 | U19: 4769.1521 | V19: 4027.1021 | W19: 5719.1304 | X19: 6098.4388 | Y19: 6760.5273 | Z19: 7074.0238 | AA19: 6935.6339 | AB19: {=(AA19/V19)^(1/5)-1} | AD19: Text_503 | AF19: 2890.2693 | AG19: 4080.6395 | AH19: 4727.3275 | AI19: 3382.0824 | AJ19: {=AJ20*AJ14} | AK19: {=AK20*AK14} | AL19: {=AL20*AL14} | AM19: {=AM20*AM14} | AN19: {=AN20*AN14} | AO19: {=(AN19/AI19)^(1/5)-1} | AQ19: Text_503 | AS19: 2375.0264 | AT19: 4500.9873 | AU19: 4740.6438 | AV19: 4532.9068 | AW19: {=AW20*AW14} | AX19: {=AX20*AX14} | AY19: {=AY20*AY14} | AZ19: {=AZ20*AZ14} | BA19: {=BA20*BA14} | BB19: {=(BA19/AV19)^(1/5)-1}
B20: Text_504 | D20: {=D19/D14} | E20: {=E19/E14} | F20: {=F19/F14} | G20: {=G19/G14} | H20: {=H19/H14} | I20: {=H20+0.2%} | J20: {=I20+0.2%} | K20: {=J20+0.2%} | L20: {=K20+0.2%} | M20: {=L20+0.2%} | Q20: Text_504 | S20: 0.40446482 | T20: 0.42808474 | U20: 0.41904121 | V20: 0.41763974 | W20: 0.40323277 | X20: 0.40811906 | Y20: 0.38457936 | Z20: 0.40363144 | AA20: 0.41878413 | AD20: Text_504 | AF20: 0.37903704 | AG20: 0.40583284 | AH20: 0.40041046 | AI20: 0.38343337 | AJ20: 0.39441522 | AK20: {=AJ20+1%} | AL20: {=AK20+1%} | AM20: {=AL20+1%} | AN20: {=AM20+1%} | AQ20: Text_504 | AS20: 0.38706033 | AT20: 0.44559113 | AU20: 0.41098939 | AV20: 0.38059632 | AW20: 0.37743849 | AX20: 0.41302705 | AY20: 0.39867113 | AZ20: 0.42498615 | BA20: 0.41871992
B21: Text_505 | F21: {=(F19-E19)/(F14-E14)} | G21: {=(G19-F19)/(G14-F14)} | H21: {=(H19-G19)/(H14-G14)} | I21: {=(I19-H19)/(I14-H14)} | J21: {=(J19-I19)/(J14-I14)} | K21: {=(K19-J19)/(K14-J14)} | L21: {=(L19-K19)/(L14-K14)} | M21: {=(M19-L19)/(M14-L14)} | Q21: Text_505 | T21: 0.53851155 | U21: 0.31460331 | V21: 0.62135393 | W21: 0.52612783 | X21: 0.53581131 | Y21: 0.5220511 | Z21: 0.48045786 | AA21: 0.49353025 | AD21: Text_505 | AG21: 0.4967005 | AH21: 0.3328902 | AI21: 0.58138989 | AJ21: {=(AJ19-AI19)/(AJ14-AI14)} | AK21: {=(AK19-AJ19)/(AK14-AJ14)} | AL21: {=(AL19-AK19)/(AL14-AK14)} | AM21: {=(AM19-AL19)/(AM14-AL14)} | AN21: {=(AN19-AM19)/(AN14-AM14)} | AQ21: Text_505 | AT21: 0.5246321 | AU21: 0.31428702 | AV21: 0.61708918 | AW21: {=(AW19-AV19)/(AW14-AV14)} | AX21: {=(AX19-AW19)/(AX14-AW14)} | AY21: {=(AY19-AX19)/(AY14-AX14)} | AZ21: {=(AZ19-AY19)/(AZ14-AY14)} | BA21: {=(BA19-AZ19)/(BA14-AZ14)}
B22: Text_15 | F22: {=F19/E19-1} | G22: {=G19/F19-1} | H22: {=H19/G19-1} | I22: {=I19/H19-1} | J22: {=J19/I19-1} | K22: {=K19/J19-1} | L22: {=L19/K19-1} | M22: {=M19/L19-1} | Q22: Text_15 | T22: 0.45760296 | U22: 0.1109985 | V22: -0.099184448 | W22: 0.3056772 | X22: 0.073748034 | Y22: 0.090638057 | Z22: 0.16190947 | AA22: 0.15206149 | AD22: Text_15 | AG22: 0.41170818 | AH22: 0.10359983 | AI22: -0.089891081 | AJ22: {=AJ19/AI19-1} | AK22: {=AK19/AJ19-1} | AL22: {=AL19/AK19-1} | AM22: {=AM19/AL19-1} | AN22: {=AN19/AM19-1} | AQ22: Text_15 | AT22: 0.46136488 | AU22: 0.10336893 | AV22: -0.096583517 | AW22: {=AW19/AV19-1} | AX22: {=AX19/AW19-1} | AY22: {=AY19/AX19-1} | AZ22: {=AZ19/AY19-1} | BA22: {=BA19/AZ19-1}
B23: Text_506 | D23: {='Model'!AG257} | E23: {='Model'!AL257} | F23: {='Model'!AQ257} | G23: {='Model'!AV257} | H23: {='Model'!BA257} | I23: {='Model'!BF257} | J23: {='Model'!BK257} | K23: {='Model'!BP257} | L23: {='Model'!BU257} | M23: {='Model'!BZ257} | Q23: Text_506 | S23: 0.30671474 | T23: 0.35574635 | U23: 0.33096949 | V23: 0.34697412 | W23: 0.37628423 | X23: 0.34742761 | Y23: 0.38091697 | Z23: 0.39385367 | AA23: 0.39385226 | AD23: Text_506 | AF23: 0.34183048 | AG23: 0.33635838 | AH23: 0.34243451 | AI23: 0.31054442 | AJ23: {=$W$23/$W$20*AJ20} | AK23: {=AJ23/AJ20*AK20} | AL23: {=AK23/AK20*AL20} | AM23: {=AL23/AL20*AM20} | AN23: {=AM23/AM20*AN20} | AQ23: Text_506 | AS23: 0.3091522 | AT23: 0.37115345 | AU23: 0.33113273 | AV23: 0.34046528 | AW23: {=$W$23/$W$20*AW20} | AX23: {=AW23/AW20*AX20} | AY23: {=AX23/AX20*AY20} | AZ23: {=AY23/AY20*AZ20} | BA23: {=AZ23/AZ20*BA20}
B24: Text_507 | D24: {='Model'!AG269} | E24: {='Model'!AL269} | F24: {='Model'!AQ269} | G24: {='Model'!AV269} | H24: {='Model'!BA269} | I24: {='Model'!BF269} | J24: {='Model'!BK269} | K24: {='Model'!BP269} | L24: {='Model'!BU269} | M24: {='Model'!BZ269} | Q24: Text_507 | S24: 174.41852 | T24: 173.20879 | U24: 170.51349 | V24: 122.10507 | W24: 109.12925 | X24: 126.88819 | Y24: 110.06263 | Z24: 102.43461 | AA24: 117.03693 | AD24: Text_507 | AF24: 172.99374 | AG24: 155.52184 | AH24: 129.70707 | AI24: 144.59475 | AJ24: {=AI24*(1+AJ25)} | AK24: {=AJ24*(1+AK25)} | AL24: {=AK24*(1+AL25)} | AM24: {=AL24*(1+AM25)} | AN24: {=AM24*(1+AN25)} | AQ24: Text_507 | AS24: 138.70743 | AT24: 122.08038 | AU24: 155.03268 | AV24: 142.92788 | AW24: {=AV24*(1+AW25)} | AX24: {=AW24*(1+AX25)} | AY24: {=AX24*(1+AY25)} | AZ24: {=AY24*(1+AZ25)} | BA24: {=AZ24*(1+BA25)}
B25: Text_15 | F25: {=F24/E24-1} | G25: {=G24/F24-1} | H25: {=H24/G24-1} | I25: {=I24/H24-1} | J25: {=J24/I24-1} | K25: {=K24/J24-1} | L25: {=L24/K24-1} | M25: {=M24/L24-1} | Q25: Text_15 | T25: -0.025647677 | U25: -0.057633025 | V25: -0.044235478 | W25: -0.018449472 | X25: -0.016231046 | Y25: -0.018430476 | Z25: -0.020725208 | AA25: -0.021299146 | AD25: Text_15 | AG25: -0.025048465 | AH25: -0.079489619 | AI25: -0.029653351 | AJ25: -0.019846117 | AK25: -0.020553059 | AL25: -0.019704615 | AM25: -0.019277001 | AN25: -0.020258272 | AQ25: Text_15 | AT25: -0.026195764 | AU25: -0.078877435 | AV25: -0.028067509 | AW25: {=AJ25} | AX25: {=AW25} | AY25: {=AX25} | AZ25: {=AY25} | BA25: {=AZ25}
B26: Text_508 | D26: {='Model'!AG274} | E26: {='Model'!AL274} | F26: {='Model'!AQ274} | G26: {='Model'!AV274} | H26: {=(H23*H14)/H24} | I26: {='Model'!BF274} | J26: {='Model'!BK274} | K26: {='Model'!BP274} | L26: {='Model'!BU274} | M26: {='Model'!BZ274} | N26: {=(M26/H26)^(1/5)-1} | Q26: Text_508 | S26: 14.714737 | T26: 18.718143 | U26: 29.978649 | V26: 28.314139 | W26: 34.317464 | X26: 39.108877 | Y26: 42.099591 | Z26: 48.020116 | AA26: 44.982914 | AB26: {=(AA26/V26)^(1/5)-1} | AD26: Text_508 | AF26: 14.290277 | AG26: 22.638009 | AH26: 27.177506 | AI26: 22.539505 | AJ26: {=(AJ23*AJ14)/AJ24} | AK26: {=(AK23*AK14)/AK24} | AL26: {=(AL23*AL14)/AL24} | AM26: {=(AM23*AM14)/AM24} | AN26: {=(AN23*AN14)/AN24} | AO26: {=(AN26/AI26)^(1/5)-1} | AQ26: Text_508 | AS26: 17.1249 | AT26: 18.34339 | AU26: 25.379172 | AV26: 25.557547 | AW26: {=(AW23*AW14)/AW24} | AX26: {=(AX23*AX14)/AX24} | AY26: {=(AY23*AY14)/AY24} | AZ26: {=(AZ23*AZ14)/AZ24} | BA26: {=(BA23*BA14)/BA24} | BB26: {=(BA26/AV26)^(1/5)-1}
B27: Text_15 | F27: {=F26/E26-1} | G27: {=G26/F26-1} | H27: {=H26/G26-1} | I27: {=I26/H26-1} | J27: {=J26/I26-1} | K27: {=K26/J26-1} | L27: {=L26/K26-1} | M27: {=M26/L26-1} | Q27: Text_15 | T27: 0.46577486 | U27: 0.18604312 | V27: -0.049399325 | W27: 0.34704858 | X27: 0.078061672 | Y27: 0.11336365 | Z27: 0.18596351 | AA27: 0.18802246 | AD27: Text_15 | AG27: 0.45113297 | AH27: 0.2037524 | AI27: -0.067164058 | AJ27: {=AJ26/AI26-1} | AK27: {=AK26/AJ26-1} | AL27: {=AL26/AK26-1} | AM27: {=AM26/AL26-1} | AN27: {=AN26/AM26-1} | AQ27: Text_15 | AT27: 0.43385999 | AU27: 0.18651698 | AV27: -0.066664747 | AW27: {=AW26/AV26-1} | AX27: {=AX26/AW26-1} | AY27: {=AY26/AX26-1} | AZ27: {=AZ26/AY26-1} | BA27: {=BA26/AZ26-1}
AD28: Text_509 | AI28: {=AI26/$V$26-1} | AJ28: {=AJ26/$W$26-1} | AK28: {=AK26/$X$26-1} | AL28: {=AL26/$Y$26-1} | AM28: {=AM26/$Z$26-1} | AN28: {=AN26/$AA$26-1} | AQ28: Text_509 | AV28: {=AV26/$V$26-1} | AW28: {=AW26/$W$26-1} | AX28: {=AX26/$X$26-1} | AY28: {=AY26/$Y$26-1} | AZ28: {=AZ26/$Z$26-1} | BA28: {=BA26/$AA$26-1}
B29: Text_276 | D29: {='Model'!AG327} | E29: {='Model'!AL327} | F29: {='Model'!AQ327} | G29: {='Model'!AV327} | H29: {='Model'!BA327} | I29: {='Model'!BF327} | J29: {='Model'!BK327} | K29: {='Model'!BP327} | L29: {='Model'!BU327} | M29: {='Model'!BZ327} | N29: {=(M29/H29)^(1/5)-1} | Q29: Text_276 | S29: 13.12498 | T29: 21.42009 | U29: 26.569683 | V29: 24.953499 | W29: 38.020409 | X29: 35.150765 | Y29: 36.930816 | Z29: 41.523585 | AA29: 44.414547 | AB29: {=(AA29/V29)^(1/5)-1} | AD29: Text_276 | AF29: 12.938442 | AG29: 18.066787 | AH29: 27.738234 | AI29: 22.998215 | AJ29: {=AJ31*AJ26} | AK29: {=AK31*AK26} | AL29: {=AL31*AL26} | AM29: {=AM31*AM26} | AN29: {=AN31*AN26} | AO29: {=(AN29/AI29)^(1/5)-1} | AQ29: Text_276 | AS29: 13.0402 | AT29: 18.684975 | AU29: 19.483934 | AV29: 18.088668 | AW29: {=AW31*AW26} | AX29: {=AX31*AX26} | AY29: {=AY31*AY26} | AZ29: {=AZ31*AZ26} | BA29: {=BA31*BA26} | BB29: {=(BA29/AV29)^(1/5)-1}
B30: Text_15 | F30: {=F29/E29-1} | G30: {=G29/F29-1} | H30: {=H29/G29-1} | I30: {=I29/H29-1} | J30: {=J29/I29-1} | K30: {=K29/J29-1} | L30: {=L29/K29-1} | M30: {=M29/L29-1} | Q30: Text_15 | T30: 0.57173214 | U30: 0.16990829 | V30: -0.049682821 | W30: 0.46475623 | X30: 0.083516878 | Y30: 0.072167984 | Z30: 0.15855497 | AA30: 0.2022235 | AD30: Text_15 | AG30: 0.60737296 | AH30: 0.18874619 | AI30: -0.06433417 | AJ30: {=AJ29/AI29-1} | AK30: {=AK29/AJ29-1} | AL30: {=AL29/AK29-1} | AM30: {=AM29/AL29-1} | AN30: {=AN29/AM29-1} | AQ30: Text_15 | AT30: 0.56119484 | AU30: 0.20463936 | AV30: -0.06649442 | AW30: {=AW29/AV29-1} | AX30: {=AX29/AW29-1} | AY30: {=AY29/AX29-1} | AZ30: {=AZ29/AY29-1} | BA30: {=BA29/AZ29-1}
B31: Text_510 | F31: {=F29/F26} | G31: {=G29/G26} | H31: {=H29/H26} | I31: {=I29/I26} | J31: {=J29/J26} | K31: {=K29/K26} | L31: {=L29/L26} | M31: {=M29/M26} | Q31: Text_510 | T31: 0.87874333 | U31: 0.98502564 | V31: 0.95270194 | W31: 1.0539539 | X31: 0.98931033 | Y31: 1.0014375 | Z31: 0.87910091 | AA31: 0.92068736 | AD31: Text_510 | AG31: 0.88336709 | AH31: 0.99475161 | AI31: 0.97699162 | AJ31: 1.0470063 | AK31: 1.0583954 | AL31: 0.94468046 | AM31: 0.98474635 | AN31: 0.94280465 | AQ31: Text_510 | AT31: 0.90133896 | AU31: 0.90170707 | AV31: 0.93351408 | AW31: 0.92068454 | AX31: 0.89945723 | AY31: 0.9078822 | AZ31: 0.90532157 | BA31: 1.0099231
B33: Text_300 | D33: {='Model'!AG355} | E33: {='Model'!AL355} | F33: {='Model'!AQ355} | G33: {='Model'!AV355} | H33: {='Model'!BA355} | I33: {='Model'!BF355} | J33: {='Model'!BK355} | K33: {='Model'!BP355} | L33: {='Model'!BU355} | M33: {='Model'!BZ355} | Q33: Text_300 | S33: -1046.5941 | T33: -4692.2802 | U33: -2583.7603 | V33: -1937.6521 | W33: -3493.7876 | X33: -2381.4075 | Y33: -2173.2878 | Z33: -1898.6086 | AA33: -1385.6609 | AD33: Text_300 | AF33: -855.87193 | AG33: -3723.9584 | AH33: -2831.8422 | AI33: -1754.1206 | AQ33: Text_300 | AS33: -838.44086 | AT33: -4441.3023 | AU33: -2273.6564 | AV33: -1992.3166
B34: Text_511 | D34: {=-D33/D18} | E34: {=-E33/E18} | F34: {=-F33/F18} | G34: {=-G33/G18} | H34: {=-H33/H18} | I34: {=-I33/I18} | J34: {=-J33/J18} | K34: {=-K33/K18} | ... M34: {=-M33/M18} | Q34: Text_511 | S34: 0.32726024 | T34: 0.88592794 | U34: 0.52917925 | V34: 0.49362099 | W34: 0.54845909 | X34: 0.43433248 | Y34: 0.38228046 | Z34: 0.27248358 | AA34: 0.19335923 | AD34: Text_511 | AF34: 0.31231546 | AG34: 0.88458492 | AH34: 0.56961905 | AI34: 0.47971185 | AQ34: Text_511 | AS34: 0.31158 | AT34: 0.876932 | AU34: 0.55733499 | AV34: 0.4818766
Q36: Text_512 | S36: {=$R$3/S26} | T36: {=$R$3/T26} | U36: {=$R$3/U26} | V36: {=$C$3/V26} | W36: {=$C$3/W26} | X36: {=$C$3/X26} | Y36: {=$C$3/Y26} | Z36: {=$C$3/Z26} | AA36: {=$C$3/AA26} | AD36: Text_513 | AF36: 43.136996 | AG36: 21.624483 | AH36: 21.200955 | AI36: {=$C$3/AI26} | AJ36: {=$AE$3/AJ26} | AK36: {=$AE$3/AK26} | AL36: {=$AE$3/AL26} | AM36: {=$AE$3/AM26} | AN36: {=$AE$3/AN26} | AQ36: Text_514 | AS36: {=$AR$3/AS26} | AT36: 23.382214 | AU36: 23.707847 | AV36: {=$C$3/AV26} | AW36: {=$C$3/AW26} | AX36: {=$C$3/AX26} | AY36: {=$C$3/AY26} | AZ36: {=$C$3/AZ26} | BA36: {=$C$3/BA26}
Q37: Text_515 | S37: {=S29/$R$3} | T37: {=T29/$R$3} | U37: {=U29/$R$3} | V37: {=V29/$R$3} | W37: {=W29/$R$3} | X37: {=X29/$R$3} | Y37: {=Y29/$R$3} | Z37: {=Z29/$R$3} | AA37: {=AA29/$R$3} | AD37: Text_516 | AF37: 0.022834103 | AG37: 0.036465877 | AH37: 0.044263938 | AI37: {=AI29/$R$3} | AJ37: {=AJ29/$AE$3} | AK37: {=AK29/$AE$3} | AL37: {=AL29/$AE$3} | AM37: {=AM29/$AE$3} | AN37: {=AN29/$AE$3} | AQ37: Text_516 | AS37: {=AS29/$AR$3} | AT37: 0.052147746 | AU37: 0.048515994 | AV37: {=AV29/$R$3} | AW37: {=AW29/$R$3} | AX37: {=AX29/$R$3} | AY37: {=AY29/$R$3} | AZ37: {=AZ29/$R$3} | BA37: {=BA29/$R$3}
Q39: Text_517 | X39: 23.349809 | Y39: 24.992951 | Z39: 25.11139 | AA39: 23.116154 | AD39: Text_518 | AK39: 21.817499 | AL39: 19.317465 | AM39: 20.910897 | AN39: 21.933132 | AQ39: Text_519 | AX39: 20.93758 | AY39: 19.865447 | AZ39: 21.570551 | BA39: 17.002107
B40: Text_520 | Q40: Text_521 | X40: {=X39*X26} | Y40: {=Y39*Y26} | Z40: {=Z39*Z26} | AA40: {=AA39*AA26} | AD40: Text_522 | AK40: {=AK39*AK26} | AL40: {=AL39*AL26} | AM40: {=AM39*AM26} | AN40: {=AN39*AN26} | AQ40: Text_523 | AX40: {=AX39*AX26} | AY40: {=AY39*AY26} | AZ40: {=AZ39*AZ26} | BA40: {=BA39*BA26}
B41: {=C3} | G41: Text_483 | H41: Text_484 | I41: Text_485 | K41: Text_524 | Q41: Text_525 | X41: {=X40/$C$3-1} | Y41: {=Y40/$C$3-1} | Z41: {=Z40/$C$3-1} | AA41: {=AA40/$C$3-1} | AD41: Text_525 | AK41: {=AK40/$C$3-1} | AL41: {=AL40/$C$3-1} | AM41: {=AM40/$C$3-1} | AN41: {=AN40/$C$3-1} | AQ41: Text_525 | AX41: {=AX40/$C$3-1} | AY41: {=AY40/$C$3-1} | AZ41: {=AZ40/$C$3-1} | BA41: {=BA40/$C$3-1}
L42: Text_526 | Q42: Text_527 | X42: {=X40/X29} | Y42: {=Y40/Y29} | Z42: {=Z40/Z29} | AA42: {=AA40/AA29} | AD42: Text_527 | AK42: {=AK40/AK29} | AL42: {=AL40/AL29} | AM42: {=AM40/AM29} | AN42: {=AN40/AN29} | AQ42: Text_527 | AX42: {=AX40/AX29} | AY42: {=AY40/AY29} | AZ42: {=AZ40/AZ29} | BA42: {=BA40/BA29}
B43: Text_528 | G43: {=O7} | H43: {=AO7} | I43: {=BB7} | K43: Text_529 | N43: {=(1/2*E26)+(1/2*D26)}
B44: Text_530 | G44: {=O9} | H44: {=AO9} | I44: {=BB9} | K44: Text_531 | N44: {=(1/2*F26)+(1/2*E26)} | O44: {=N44/N43-1} | AD44: Text_532 | AI44: Text_533 | AQ44: Text_534 | AV44: Text_535
...

Sheet Sheet_5
B2: Text_607 | C2: 0.085716013
B3: Text_608 | C3: 0.029498193
B4: Text_609 | C4: {='Model'!BF252}
B5: Text_610 | C5: {=TODAY()}
B6: Text_611 | C6: -0.34310022
D7: 45657 | E7: {=EOMONTH(D7,12)} | F7: {=EOMONTH(E7,12)} | G7: {=EOMONTH(F7,12)} | H7: {=EOMONTH(G7,12)} | I7: {=EOMONTH(H7,12)} | J7: {=EOMONTH(I7,12)} | K7: {=EOMONTH(J7,12)} | L7: {=EOMONTH(K7,12)} | ... AQ7: {=EOMONTH(AP7,12)}
D8: 1916.6395 | E8: 1690.4839 | F8: 2072.0185 | G8: 2306.824 | H8: 2268.0555 | I8: 1765.3299 | J8: 2170.2849 | K8: 1803.9377 | L8: 1802.9591 | M8: 2337.1952 | N8: 1830.3307 | O8: 1842.2833 | P8: 1629.3321 | Q8: 2339.0211 | R8: 2276.5233 | S8: 2142.8495 | T8: 2244.2169 | U8: 1756.9325 | V8: 2007.9587 | W8: 1921.4165 | X8: 1711.8717 | Y8: 2033.6547 | Z8: 2390.3333 | AA8: 1670.4004 | AB8: 1877.1648 | AC8: 1809.3006 | AD8: 1835.2803 | AE8: 2386.0797 | AF8: 2025.7911 | AG8: 2025.3251 | AH8: 2268.0889 | AI8: 1770.9926 | AJ8: 2045.527 | AK8: 1999.3918 | AL8: 2137.7769 | AM8: 2470.4357 | AN8: 2282.0259 | AO8: 1976.8005 | AP8: 2332.1658 | AQ8: 1791.2685
B9: Text_612 | D9: {=(D7-$C$5)/365} | E9: {=(E7-$C$5)/365} | F9: {=(F7-$C$5)/365} | G9: {=(G7-$C$5)/365} | H9: {=(H7-$C$5)/365} | I9: {=(I7-$C$5)/365} | J9: {=(J7-$C$5)/365} | K9: {=(K7-$C$5)/365} | ... AQ9: {=(AQ7-$C$5)/365}
B10: Text_613 | D10: {=1/(1+$C$2)^D9} | E10: {=1/(1+$C$2)^E9} | F10: {=1/(1+$C$2)^F9} | G10: {=1/(1+$C$2)^G9} | H10: {=1/(1+$C$2)^H9} | I10: {=1/(1+$C$2)^I9} | J10: {=1/(1+$C$2)^J9} | K10: {=1/(1+$C$2)^K9} | ... AQ10: {=1/(1+$C$2)^AQ9}
B12: Text_614 | D12: {='Model'!BA94} | E12: {='Model'!BF94} | F12: {='Model'!BK94} | G12: {='Model'!BP94} | H12: {='Model'!BU94} | I12: {=H12*(1+I13)} | J12: {=I12*(1+J13)} | K12: {=J12*(1+K13)} | L12: {=K12*(1+L13)} | M12: {=L12*(1+M13)} | N12: {=M12*(1+N13)} | O12: {=N12*(1+O13)} | P12: {=O12*(1+P13)} | ... AQ12: {=AP12*(1+AQ13)} | AR12: {=(AQ12/D12)^(1/39)-1}
B13: Text_15 | E13: {=E12/D12-1} | F13: {=F12/E12-1} | G13: {=G12/F12-1} | H13: {=H12/G12-1} | I13: {=I15} | J13: {=J15} | K13: {=K15} | L13: {=L15} | M13: {=M15} | N13: {=N15} | O13: {=O15} | P13: {=P15} | ... AQ13: {=AQ15}
B14: Text_615 | D14: {='Model'!BA101} | E14: {='Model'!BF101} | F14: {='Model'!BK101} | G14: {='Model'!BP101} | H14: {='Model'!BU101} | I14: {=I19/I16} | J14: {=J19/J16} | K14: {=K19/K16} | L14: {=L19/L16} | M14: {=M19/M16} | N14: {=N19/N16} | O14: {=O19/O16} | P14: {=P19/P16} | ... AQ14: {=AQ19/AQ16} | AR14: {=(AQ14/D14)^(1/39)-1}
B15: Text_15 | E15: {=E14/D14-1} | F15: {=F14/E14-1} | G15: {=G14/F14-1} | H15: {=H14/G14-1} | I15: {=I14/H14-1} | J15: {=J14/I14-1} | K15: {=K14/J14-1} | L15: {=L14/K14-1} | ... AQ15: {=AQ14/AP14-1}
B16: Text_616 | D16: {=D19/D14} | E16: {=E19/E14} | F16: {=F19/F14} | G16: {=G19/G14} | H16: {=H19/H14} | I16: {=H16-0.2%} | J16: {=I16-0.2%} | K16: {=J16-0.2%} | L16: {=K16-0.2%} | M16: {=L16-0.2%} | N16: {=M16-0.2%} | O16: {=N16-0.2%} | P16: {=O16-0.1%} | Q16: {=P16-0.1%} | R16: {=Q16-0.1%} | S16: {=R16-0.1%} | T16: {=S16-0.1%} | U16: {=T16-0.1%} | V16: {=U16-0.1%} | W16: {=V16-0.1%} | ... Z16: {=Y16-0.1%} | AA16: {=Z16} | AB16: {=AA16} | AC16: {=AB16} | AD16: {=AC16} | AE16: {=AD16} | AF16: {=AE16} | AG16: {=AF16} | AH16: {=AG16} | ... AQ16: {=AP16}
B17: Text_617 | D17: {=D19/D12} | E17: {=E19/E12} | F17: {=F19/F12} | G17: {=G19/G12} | H17: {=H19/H12} | I17: {=I19/I12} | J17: {=J19/J12} | K17: {=K19/K12} | ... AQ17: {=AQ19/AQ12}
B19: Text_618 | D19: {='Model'!BA111} | E19: {='Model'!BF111} | F19: {='Model'!BK111} | G19: {='Model'!BP111} | H19: {=G19*(1+H20)} | I19: {=H19*(1+I20)} | J19: {=I19*(1+J20)} | K19: {=J19*(1+K20)} | L19: {=K19*(1+L20)} | M19: {=L19*(1+M20)} | N19: {=M19*(1+N20)} | O19: {=N19*(1+O20)} | ... AQ19: {=AP19*(1+AQ20)} | AR19: {=(AQ19/D19)^(1/39)-1}
B20: Text_15 | E20: {=E19/D19-1} | F20: {=F19/E19-1} | G20: {=G19/F19-1} | H20: 0.11248742 | I20: {=H20} | J20: 0.11527117 | K20: -0.097872154 | L20: 0.15021162 | M20: 0.11168856 | N20: {=M20} | O20: {=N20} | P20: {=O20} | Q20: {=P20} | R20: {=Q20} | S20: {=R20} | T20: {=S20} | U20: -0.10547474 | V20: 0.15019708 | W20: 0.10001701 | X20: {=W20} | Y20: {=X20} | Z20: {=Y20} | AA20: {=Z20} | AB20: {=AA20} | AC20: {=AB20} | AD20: {=AC20} | AE20: -0.09400324 | AF20: 0.14069823 | AG20: 0.09061392 | AH20: {=AG20} | AI20: {=AH20} | AJ20: {=AI20} | AK20: {=AJ20} | AL20: {=AK20} | AM20: {=AL20} | AN20: {=AM20} | AO20: -0.099175715 | AP20: 0.15678361 | AQ20: 0.076380582
B21: Text_619 | D21: {='Valuation'!N69} | E21: {='Valuation'!N70} | F21: {='Valuation'!N71} | G21: {='Valuation'!N72} | H21: {=G21+(H19-G19)*H23} | I21: {=H21+(I19-H19)*I23} | J21: {=I21+(J19-I19)*J23} | K21: {=J21+(K19-J19)*K23} | L21: {=K21+(L19-K19)*L23} | M21: {=L21+(M19-L19)*M23} | N21: {=M21+(N19-M19)*N23} | O21: {=N21+(O19-N19)*O23} | ... AQ21: {=AP21+(AQ19-AP19)*AQ23} | AR21: {=(AQ21/D21)^(1/39)-1}
B22: Text_620 | D22: {=D21/D19} | E22: {=E21/E19} | F22: {=F21/F19} | G22: {=G21/G19} | H22: {=H21/H19} | I22: {=I21/I19} | J22: {=J21/J19} | K22: {=K21/K19} | ... AQ22: {=AQ21/AQ19}
B23: Text_621 | D23: {=(D21-C21)/(D19-C19)} | E23: {=(E21-D21)/(E19-D19)} | F23: {=(F21-E21)/(F19-E19)} | G23: {=(G21-F21)/(G19-F19)} | H23: 0.51516459 | I23: {=H23} | J23: {=I23} | K23: 0.64558336 | L23: 0.53074843 | M23: {=L23} | N23: {=M23} | O23: {=N23} | P23: {=O23} | Q23: {=P23} | R23: {=Q23} | S23: {=R23} | T23: {=S23} | U23: 0.61096658 | V23: 0.56647054 | W23: {=V23} | X23: {=W23} | Y23: {=X23} | Z23: {=Y23} | AA23: {=Z23} | AB23: {=AA23} | AC23: {=AB23} | AD23: {=AC23} | AE23: 0.61633806 | AF23: 0.55794343 | AG23: {=AF23} | AH23: {=AG23} | AI23: {=AH23} | AJ23: {=AI23} | AK23: {=AJ23} | AL23: {=AK23} | AM23: {=AL23} | AN23: {=AM23} | AO23: 0.63102431 | AP23: 0.52605638 | AQ23: {=AP23}
B24: Text_15 | E24: {=E21/D21-1} | F24: {=F21/E21-1} | G24: {=G21/F21-1} | H24: {=H21/G21-1} | I24: {=I21/H21-1} | J24: {=J21/I21-1} | K24: {=K21/J21-1} | L24: {=L21/K21-1} | ... AQ24: {=AQ21/AP21-1}
B25: Text_622 | D25: {=D21*(1-$C$4)} | E25: {=E21*(1-$C$4)} | F25: {=F21*(1-$C$4)} | G25: {=G21*(1-$C$4)} | H25: {=H21*(1-$C$4)} | I25: {=I21*(1-$C$4)} | J25: {=J21*(1-$C$4)} | K25: {=K21*(1-$C$4)} | ... AQ25: {=AQ21*(1-$C$4)} | AR25: {=(AQ25/D25)^(1/39)-1}
B26: Text_623 | D26: {=D27*D19} | E26: {=E27*E19} | F26: {=F27*F19} | G26: {=G27*G19} | H26: {=H27*H19} | I26: {=I27*I19} | J26: {=J27*J19} | K26: {=K27*K19} | ... AQ26: {=AQ27*AQ19} | AR26: {=(AQ26/D26)^(1/39)-1}
B27: Text_100 | D27: 0.039358675 | E27: {=D27-0.5%} | F27: {=E27-0.5%} | G27: {=F27-0.5%} | H27: {=G27} | I27: {=H27} | J27: {=I27} | K27: {=J27} | L27: {=K27} | M27: {=L27} | N27: {=M27} | O27: {=N27} | ... AQ27: {=AP27}
B28: Text_611 | D28: {=(0.5*'Model'!BA309)+(0.5*'Model'!BF309)} | E28: {=(0.5*'Model'!BF309)+(0.5*'Model'!BK309)} | F28: {=(0.5*'Model'!BK309)+(0.5*'Model'!BP309)} | G28: {=(0.5*'Model'!BP309)+(0.5*'Model'!BU309)} | H28: {=(H19-G19)*$C$6} | I28: {=(I19-H19)*$C$6} | J28: {=(J19-I19)*$C$6} | K28: {=(K19-J19)*$C$6} | L28: {=(L19-K19)*$C$6} | M28: {=(M19-L19)*$C$6} | N28: {=(N19-M19)*$C$6} | O28: {=(O19-N19)*$C$6} | ... AQ28: {=(AQ19-AP19)*$C$6}
B29: Text_624 | E29: {=E28/(E19-D19)} | F29: {=F28/(F19-E19)} | G29: {=G28/(G19-F19)} | H29: {=H28/(H19-G19)} | I29: {=I28/(I19-H19)} | J29: {=J28/(J19-I19)} | K29: {=K28/(K19-J19)} | L29: {=L28/(L19-K19)} | ... AQ29: {=AQ28/(AQ19-AP19)}
B30: Text_625 | D30: {=D28/D19} | E30: {=E28/E19} | F30: {=F28/F19} | G30: {=G28/G19} | H30: {=H28/H19} | I30: {=I28/I19} | J30: {=J28/J19} | K30: {=K28/K19} | ... AQ30: {=AQ28/AQ19}
B31: Text_626 | D31: {=(0.5*'Model'!BA320)+(0.5*'Model'!BF320)} | E31: {=(0.5*'Model'!BF320)+(0.5*'Model'!BK320)} | F31: {=(0.5*'Model'!BK320)+(0.5*'Model'!BP320)} | G31: {=(0.5*'Model'!BP320)+(0.5*'Model'!BU320)} | H31: {=-H32*H19} | I31: {=-I32*I19} | J31: {=-J32*J19} | K31: {=-K32*K19} | L31: {=-L32*L19} | M31: {=-M32*M19} | N31: {=M31*(1+N20)} | O31: {=N31*(1+O20)} | P31: {=O31*(1+P20)} | Q31: {=P31*(1+Q20)} | R31: {=Q31*(1+R20)} | S31: {=R31*(1+S20)} | T31: {=S31*(1+T20)} | U31: {=-U32*U19} | V31: {=-V32*V19} | W31: {=-W32*W19} | X31: {=W31*(1+X20)} | Y31: {=X31*(1+Y20)} | Z31: {=Y31*(1+Z20)} | AA31: {=Z31*(1+AA20)} | AB31: {=AA31*(1+AB20)} | AC31: {=AB31*(1+AC20)} | AD31: {=AC31*(1+AD20)} | AE31: {=-AE32*AE19} | AF31: {=-AF32*AF19} | AG31: {=-AG32*AG19} | AH31: {=AG31*(1+AH20)} | AI31: {=AH31*(1+AI20)} | AJ31: {=AI31*(1+AJ20)} | AK31: {=AJ31*(1+AK20)} | AL31: {=AK31*(1+AL20)} | AM31: {=AL31*(1+AM20)} | AN31: {=AM31*(1+AN20)} | AO31: {=-AO32*AO19} | AP31: {=-AP32*AP19} | AQ31: {=-AQ32*AQ19} | AR31: {=(AQ31/D31)^(1/39)-1}
B32: Text_100 | D32: {=-D31/D19} | E32: {=-E31/E19} | F32: {=-F31/F19} | G32: {=-G31/G19} | H32: {=G32-0.1%} | I32: {=H32-0.1%} | J32: {=I32-0.1%} | K32: 0.031205783 | L32: {=K32-0.1%} | M32: {=L32-0.1%} | N32: {=-N31/N19} | O32: {=-O31/O19} | P32: {=-P31/P19} | Q32: {=-Q31/Q19} | R32: {=-R31/R19} | S32: {=-S31/S19} | T32: {=-T31/T19} | U32: 0.029568374 | V32: {=U32-0.1%} | W32: {=V32-0.1%} | X32: {=-X31/X19} | Y32: {=-Y31/Y19} | Z32: {=-Z31/Z19} | AA32: {=-AA31/AA19} | AB32: {=-AB31/AB19} | AC32: {=-AC31/AC19} | AD32: {=-AD31/AD19} | AE32: 0.031003079 | AF32: {=AE32-0.1%} | AG32: {=AF32-0.1%} | AH32: {=-AH31/AH19} | AI32: {=-AI31/AI19} | AJ32: {=-AJ31/AJ19} | AK32: {=-AK31/AK19} | AL32: {=-AL31/AL19} | AM32: {=-AM31/AM19} | AN32: {=-AN31/AN19} | AO32: 0.028501945 | AP32: {=AO32-0.1%} | AQ32: {=AP32-0.1%}
B33: Text_15 | E33: {=E31/D31-1} | F33: {=F31/E31-1} | G33: {=G31/F31-1} | H33: {=H31/G31-1} | I33: {=I31/H31-1} | J33: {=J31/I31-1} | K33: {=K31/J31-1} | L33: {=L31/K31-1} | ... AQ33: {=AQ31/AP31-1}
B34: Text_627 | D34: {=D25+D28+D31+D26} | E34: {=E25+E28+E31+E26} | F34: {=F25+F28+F31+F26} | G34: {=G25+G28+G31+G26} | H34: {=H25+H28+H31+H26} | I34: {=I25+I28+I31+I26} | J34: {=J25+J28+J31+J26} | K34: {=K25+K28+K31+K26} | ... AQ34: {=AQ25+AQ28+AQ31+AQ26} | AR34: {=(AQ34/D34)^(1/39)-1}
B35: Text_15 | E35: {=E34/D34-1} | F35: {=F34/E34-1} | G35: {=G34/F34-1} | H35: {=H34/G34-1} | I35: {=I34/H34-1} | J35: {=J34/I34-1} | K35: {=K34/J34-1} | L35: {=L34/K34-1} | ... AQ35: {=AQ34/AP34-1}
B36: Text_628 | D36: {=D34/(D21+D26)} | E36: {=E34/(E21+E26)} | F36: {=F34/(F21+F26)} | G36: {=G34/(G21+G26)} | H36: {=H34/(H21+H26)} | I36: {=I34/(I21+I26)} | J36: {=J34/(J21+J26)} | K36: {=K34/(K21+K26)} | ... AQ36: {=AQ34/(AQ21+AQ26)}
B37: Text_629 | D37: {=D34/(1+$C$2)^D9} | E37: {=E34/(1+$C$2)^E9} | F37: {=F34/(1+$C$2)^F9} | G37: {=G34/(1+$C$2)^G9} | H37: {=H34/(1+$C$2)^H9} | I37: {=I34/(1+$C$2)^I9} | J37: {=J34/(1+$C$2)^J9} | K37: {=K34/(1+$C$2)^K9} | ... AQ37: {=AQ34/(1+$C$2)^AQ9}
B39: Text_630 | C39: {='Model'!AW388-'Model'!AW377-'Model'!AW379-'Model'!AW351} | D39: {=C39-D31-D28-D26} | E39: {=D39-E31-E28-E26} | F39: {=E39-F31-F28-F26} | G39: {=F39-G31-G28-G26} | H39: {=G39-H31-H28-H26} | I39: {=H39-I31-I28-I26} | J39: {=I39-J31-J28-J26} | K39: {=J39-K31-K28-K26} | ... AQ39: {=AP39-AQ31-AQ28-AQ26} | AR39: {=(AQ39/D39)^(1/39)-1}
B40: Text_631 | D40: {=D25/D39} | E40: {=E25/E39} | F40: {=F25/F39} | G40: {=G25/G39} | H40: {=H25/H39} | I40: {=I25/I39} | J40: {=J25/J39} | K40: {=K25/K39} | ... AQ40: {=AQ25/AQ39}
B42: Text_632 | C42: {=SUM(D37:AQ37)}
B43: Text_633 | C43: {=(AQ34*(1+C3))/(C2-C3)}
B44: Text_634 | C44: {=C43/((1+C2)^AQ9)}
